<?xml version="1.0" encoding="utf-8"?>
<robot name="ur5e_arm_parallel_gripper">

  <material name="fr_white">
    <color rgba="0.92 0.92 0.88 1.0"/>
  </material>

<!--Rotations
Clockwise 90: -1.57079632679
Counter Clockwise 90: 1.57079632679
180: 3.14159265359
-->

  <!-- ==================== UR5e Links ==================== -->
  <link name="base_link"/>

  <link name="base_link_inertia">
    <visual>
      <origin rpy="0 0 0" xyz="0 0 0"/>
      <geometry><mesh filename="package://manipulator_description/meshes/6dof/base.stl" scale="0.001 0.001 0.001"/></geometry>
      <material name="fr_white"/>
    </visual>
    <collision>
      <origin rpy="0 0 0" xyz="0 0 0"/>
      <geometry><mesh filename="package://manipulator_description/meshes/6dof/base.stl" scale="0.001 0.001 0.001"/></geometry>
    </collision>
    <inertial>
      <mass value="4.0"/>
      <origin rpy="0 0 0" xyz="0 0 0"/>
      <inertia ixx="0.00443333156" ixy="0.0" ixz="0.0" iyy="0.00443333156" iyz="0.0" izz="0.0072"/>
    </inertial>
  </link>

  <link name="shoulder_link">
    <visual>
      <origin rpy="0 0 0" xyz="0 0 0"/>
      <geometry><mesh filename="package://manipulator_description/meshes/6dof/shoulder.stl" scale="0.001 0.001 0.001"/></geometry>
      <material name="fr_white"/>
    </visual>
    <collision>
      <origin rpy="0 0 0" xyz="0 0 0"/>
      <geometry><mesh filename="package://manipulator_description/meshes/6dof/shoulder.stl" scale="0.001 0.001 0.001"/></geometry>
    </collision>
    <inertial>
      <mass value="3.7"/>
      <origin rpy="0 0 0" xyz="0 0 0"/>
      <inertia ixx="0.010267495893" ixy="0.0" ixz="0.0" iyy="0.010267495893" iyz="0.0" izz="0.00666"/>
    </inertial>
  </link>

  <link name="upper_arm_link">
    <visual>
      <origin rpy="0 0 0" xyz="0 0 0"/>
      <geometry><mesh filename="package://manipulator_description/meshes/6dof/upperarm.stl" scale="0.001 0.001 0.001"/></geometry>
      <material name="fr_white"/>
    </visual>
    <collision>
      <origin rpy="0 0 0" xyz="0 0 0"/>
      <geometry><mesh filename="package://manipulator_description/meshes/6dof/upperarm.stl" scale="0.001 0.001 0.001"/></geometry>
    </collision>
    <inertial>
      <mass value="8.393"/>
      <origin rpy="0 0 0" xyz="0 0 0"/>
      <inertia ixx="0.133885781862" ixy="0.0" ixz="0.0" iyy="0.133885781862" iyz="0.0" izz="0.0151074"/>
    </inertial>
  </link>

  <link name="forearm_link">
    <visual>
      <origin rpy="0 0 0" xyz="0 0 0"/>
      <geometry><mesh filename="package://manipulator_description/meshes/6dof/forearm.stl" scale="0.001 0.001 0.001"/></geometry>
      <material name="fr_white"/>
    </visual>
    <collision>
      <origin rpy="0 0 0" xyz="0 0 0"/>
      <geometry><mesh filename="package://manipulator_description/meshes/6dof/forearm.stl" scale="0.001 0.001 0.001"/></geometry>
    </collision>
    <inertial>
      <mass value="2.275"/>
      <origin rpy="0 0 0" xyz="0 0 0"/>
      <inertia ixx="0.0312093550996" ixy="0.0" ixz="0.0" iyy="0.0312093550996" iyz="0.0" izz="0.004095"/>
    </inertial>
  </link>

  <link name="wrist_1_link">
    <visual>
      <origin rpy="0 0 0" xyz="0 0 0"/>
      <geometry><mesh filename="package://manipulator_description/meshes/6dof/wrist1.stl" scale="0.001 0.001 0.001"/></geometry>
      <material name="fr_white"/>
    </visual>
    <collision>
      <origin rpy="0 0 0" xyz="0 0 0"/>
      <geometry><mesh filename="package://manipulator_description/meshes/6dof/wrist1.stl" scale="0.001 0.001 0.001"/></geometry>
    </collision>
    <inertial>
      <mass value="1.219"/>
      <origin rpy="0 0 0" xyz="0 0 0"/>
      <inertia ixx="0.00255989897604" ixy="0.0" ixz="0.0" iyy="0.00255989897604" iyz="0.0" izz="0.0021942"/>
    </inertial>
  </link>

  <link name="wrist_2_link">
    <visual>
      <origin rpy="0 0 0" xyz="0 0 0"/>
      <geometry><mesh filename="package://manipulator_description/meshes/6dof/wrist2.stl" scale="0.001 0.001 0.001"/></geometry>
      <material name="fr_white"/>
    </visual>
    <collision>
      <origin rpy="0 0 0" xyz="0 0 0"/>
      <geometry><mesh filename="package://manipulator_description/meshes/6dof/wrist2.stl" scale="0.001 0.001 0.001"/></geometry>
    </collision>
    <inertial>
      <mass value="1.219"/>
      <origin rpy="0 0 0" xyz="0 0 0"/>
      <inertia ixx="0.00255989897604" ixy="0.0" ixz="0.0" iyy="0.00255989897604" iyz="0.0" izz="0.0021942"/>
    </inertial>
  </link>

  <!-- wrist_3_link: flange (no mesh available) -->
  <link name="wrist_3_link">
    <inertial>
      <mass value="0.1"/>
      <origin rpy="0 0 0" xyz="0 0 0"/>
      <inertia ixx="0.0001" ixy="0.0" ixz="0.0" iyy="0.0001" iyz="0.0" izz="0.0001"/>
    </inertial>
  </link>

  <!-- tool0: end-effector frame -->
  <link name="tool0"/>

  <!-- ==================== UR5e Joints ==================== -->
  <joint name="base_link-base_link_inertia" type="fixed">
    <parent link="base_link"/>
    <child link="base_link_inertia"/>
    <origin rpy="0 0 3.14159265359" xyz="0 0 0"/>
  </joint>

  <joint name="shoulder_pan_joint" type="revolute">
    <parent link="base_link_inertia"/>
    <child link="shoulder_link"/>
    <origin rpy="0 0 0" xyz="0 0 0.0596"/>
    <axis xyz="0 0 1"/>
    <limit effort="25.0" lower="-3.14159265359" upper="3.14159265359" velocity="3.14159265359"/>
    <dynamics damping="0" friction="0"/>
  </joint>

  <joint name="shoulder_lift_joint" type="revolute">
    <parent link="shoulder_link"/>
    <child link="upper_arm_link"/>
    <origin rpy="0 0 0" xyz="0 -0.0606 0.080"/>
    <axis xyz="0 1 0"/>
    <limit effort="25.0" lower="-6.28318530718" upper="6.28318530718" velocity="3.14159265359"/>
    <dynamics damping="0" friction="0"/>
  </joint>

  <joint name="elbow_joint" type="revolute">
    <parent link="upper_arm_link"/>
    <child link="forearm_link"/>
    <origin rpy="0 0 0" xyz="0 0 0.230"/> <!-- 기존값 0.215 현재값 수정전-->
    <axis xyz="0 1 0"/>
    <limit effort="12.5" lower="-3.14159265359" upper="3.14159265359" velocity="3.14159265359"/>
    <dynamics damping="0" friction="0"/>
  </joint>

  <joint name="wrist_1_joint" type="revolute">
    <parent link="forearm_link"/>
    <child link="wrist_1_link"/>
    <origin rpy="0 0 0" xyz="0 -0.001 0.215"/>
    <axis xyz="0 1 0"/>
    <limit effort="12.5" lower="-6.28318530718" upper="6.28318530718" velocity="3.14159265359"/>
    <dynamics damping="0" friction="0"/>
  </joint>

  <joint name="wrist_2_joint" type="revolute">
    <parent link="wrist_1_link"/>
    <child link="wrist_2_link"/>
    <origin rpy="0 0 0" xyz="0 -0.0425 0.0375"/>
    <axis xyz="0 0 1"/>
    <limit effort="12.5" lower="-6.28318530718" upper="6.28318530718" velocity="3.14159265359"/>
    <dynamics damping="0" friction="0"/>
  </joint>

  <joint name="wrist_3_joint" type="revolute">
    <parent link="wrist_2_link"/>
    <child link="wrist_3_link"/>
    <origin rpy="0 0 0" xyz="0.0375 0 0.043"/>
    <axis xyz="1 0 0"/>
    <limit effort="28.0" lower="-6.28318530718" upper="6.28318530718" velocity="3.14159265359"/>
    <dynamics damping="0" friction="0"/>
  </joint>

  <joint name="wrist_3_link-tool0_fixed_joint" type="fixed">
    <parent link="wrist_3_link"/>
    <child link="tool0"/>
    <origin rpy="0 0 0" xyz="0 0 0"/>
  </joint>

  <!-- ==================== Parallel Gripper ==================== -->
  <joint name="wrist_3_link_to_gripper_base" type="fixed">
    <parent link="wrist_3_link"/>
    <child link="gripper_base"/>
    <origin rpy="0 0 0" xyz="-0.020 0 0"/>
  </joint>

  <link name="gripper_base">
    <visual>
      <origin rpy="0 0 0" xyz="0 0 0"/>
      <geometry>
        <mesh filename="package://manipulator_description/meshes/gripper_parallel/link5.stl" scale="0.001 0.001 0.001"/>
      </geometry>
      <material name="fr_white"/>
    </visual>
    <collision>
      <origin rpy="0 0 0" xyz="0 0 0"/>
      <geometry>
        <mesh filename="package://manipulator_description/meshes/gripper_parallel/link5.stl" scale="0.001 0.001 0.001"/>
      </geometry>
    </collision>
    <inertial>
      <mass value="0.160"/>
      <origin rpy="0 0 0" xyz="0.04 0 0"/>
      <inertia ixx="0.0001" ixy="0.0" ixz="0.0" iyy="0.0001" iyz="0.0" izz="0.0001"/>
    </inertial>
  </link>

  <joint name="gripper_left_joint" type="prismatic">
    <parent link="gripper_base"/>
    <child link="gripper_left_link"/>
    <origin rpy="0 0 0" xyz="0.0817 0.021 0.0"/>
    <axis xyz="0 1 0"/>
    <limit effort="1000" lower="-0.010" upper="0.019" velocity="4.8"/>
    <dynamics damping="0.1"/>
  </joint>

  <link name="gripper_left_link">
    <visual>
      <origin rpy="0 0 0" xyz="0 0 0"/>
      <geometry>
        <mesh filename="package://manipulator_description/meshes/gripper_parallel/gripper_left_palm.stl" scale="0.001 0.001 0.001"/>
      </geometry>
      <material name="fr_white"/>
    </visual>
    <collision>
      <origin rpy="0 0 0" xyz="0 0 0"/>
      <geometry>
        <mesh filename="package://manipulator_description/meshes/gripper_parallel/gripper_left_palm.stl" scale="0.001 0.001 0.001"/>
      </geometry>
    </collision>
    <inertial>
      <mass value="0.020"/>
      <origin rpy="0 0 0" xyz="0 0 0"/>
      <inertia ixx="0.00001" ixy="0.0" ixz="0.0" iyy="0.00001" iyz="0.0" izz="0.00001"/>
    </inertial>
  </link>

  <joint name="gripper_right_joint" type="prismatic">
    <parent link="gripper_base"/>
    <child link="gripper_right_link"/>
    <origin rpy="0 0 0" xyz="0.0817 -0.021 0"/>
    <axis xyz="0 -1 0"/>
    <limit effort="1000" lower="-0.010" upper="0.019" velocity="4.8"/>
    <dynamics damping="0.1"/>
    <mimic joint="gripper_left_joint" multiplier="1"/>
  </joint>

  <link name="gripper_right_link">
    <visual>
      <origin rpy="0 0 0" xyz="0 0 0"/>
      <geometry>
        <mesh filename="package://manipulator_description/meshes/gripper_parallel/gripper_right_palm.stl" scale="0.001 0.001 0.001"/>
      </geometry>
      <material name="fr_white"/>
    </visual>
    <collision>
      <origin rpy="0 0 0" xyz="0 0 0"/>
      <geometry>
        <mesh filename="package://manipulator_description/meshes/gripper_parallel/gripper_right_palm.stl" scale="0.001 0.001 0.001"/>
      </geometry>
    </collision>
    <inertial>
      <mass value="0.020"/>
      <origin rpy="0 0 0" xyz="0 0 0"/>
      <inertia ixx="0.00001" ixy="0.0" ixz="0.0" iyy="0.00001" iyz="0.0" izz="0.00001"/>
    </inertial>
  </link>

  <joint name="end_effector_joint" type="fixed">
    <parent link="gripper_base"/>
    <child link="end_effector_link"/>
    <origin rpy="0 0 0" xyz="0.126 0.0 0.0"/>
  </joint>

  <link name="end_effector_link">
    <visual>
      <origin rpy="0 0 0" xyz="0 0 0"/>
      <geometry>
        <box size="0.01 0.01 0.01"/>
      </geometry>
      <material name="fr_white"/>
    </visual>
    <collision>
      <origin rpy="0 0 0" xyz="0 0 0"/>
      <geometry>
        <box size="0.01 0.01 0.01"/>
      </geometry>
    </collision>
    <inertial>
      <mass value="0.001"/>
      <origin rpy="0 0 0" xyz="0 0 0"/>
      <inertia ixx="0.000001" ixy="0.0" ixz="0.0" iyy="0.000001" iyz="0.0" izz="0.000001"/>
    </inertial>
  </link>

  <!-- ==================== ros2_control ====================-->
  <ros2_control name="frlab_arm" type="system">
    <hardware>
      <plugin>frlab_manipulator_hardware/FrlabManipulatorHardware</plugin>
      <param name="can_interface">can0</param>
      <param name="default_velocity">0.5</param>
      <param name="read_deadline_ms">8</param>
      <param name="read_poll_timeout_ms">2</param>
      <param name="perf_log_every_n_cycles">0</param>
    </hardware>
    <joint name="shoulder_pan_joint">
      <command_interface name="position"/>
      <state_interface name="position"/>
      <state_interface name="velocity"/>
      <state_interface name="effort"/>
    </joint>
    <joint name="shoulder_lift_joint">
      <command_interface name="position"/>
      <state_interface name="position"/>
      <state_interface name="velocity"/>
      <state_interface name="effort"/>
    </joint>
    <joint name="elbow_joint">
      <command_interface name="position"/>
      <state_interface name="position"/>
      <state_interface name="velocity"/>
      <state_interface name="effort"/>
    </joint>
    <joint name="wrist_1_joint">
      <command_interface name="position"/>
      <state_interface name="position"/>
      <state_interface name="velocity"/>
      <state_interface name="effort"/>
    </joint>
    <joint name="wrist_2_joint">
      <command_interface name="position"/>
      <state_interface name="position"/>
      <state_interface name="velocity"/>
      <state_interface name="effort"/>
    </joint>
    <joint name="wrist_3_joint">
      <command_interface name="position"/>
      <state_interface name="position"/>
      <state_interface name="velocity"/>
      <state_interface name="effort"/>
    </joint>
  </ros2_control>

</robot>
